{"timestamp":"2025-09-30T12:22:08.723551","level":"info","event":"DAG bundles loaded: dags-folder","logger":"airflow.dag_processing.bundles.manager.DagBundlesManager"}
{"timestamp":"2025-09-30T12:22:08.725497","level":"info","event":"Filling up the DagBag from /opt/airflow/dags/etl_dag.py","logger":"airflow.models.dagbag.DagBag"}
{"timestamp":"2025-09-30T12:22:08.974569","level":"warning","event":"/opt/airflow/transform/normalise_data.py:40: SettingWithCopyWarning: \nA value is trying to be set on a copy of a slice from a DataFrame.\nTry using .loc[row_indexer,col_indexer] = value instead\n\nSee the caveats in the documentation: https://pandas.pydata.org/pandas-docs/stable/user_guide/indexing.html#returning-a-view-versus-a-copy\n  filtered_df['transaction_date'] = filtered_df['transaction_date'].apply(normalise_date)\n","logger":"py.warnings"}
{"timestamp":"2025-09-30T12:22:08.976895","level":"warning","event":"/opt/airflow/transform/normalise_data.py:41: SettingWithCopyWarning: \nA value is trying to be set on a copy of a slice from a DataFrame.\nTry using .loc[row_indexer,col_indexer] = value instead\n\nSee the caveats in the documentation: https://pandas.pydata.org/pandas-docs/stable/user_guide/indexing.html#returning-a-view-versus-a-copy\n  filtered_df['amount'] = pd.to_numeric(filtered_df['amount'].astype(str).str.replace(r\"[^\\d.-]\",\"\",regex=True),errors='coerce')\n","logger":"py.warnings"}
{"timestamp":"2025-09-30T12:22:08.977216","level":"warning","event":"/opt/airflow/transform/normalise_data.py:42: SettingWithCopyWarning: \nA value is trying to be set on a copy of a slice from a DataFrame.\nTry using .loc[row_indexer,col_indexer] = value instead\n\nSee the caveats in the documentation: https://pandas.pydata.org/pandas-docs/stable/user_guide/indexing.html#returning-a-view-versus-a-copy\n  filtered_df['card_name'] = card_name\n","logger":"py.warnings"}
{"timestamp":"2025-09-30T12:22:08.984759","level":"warning","event":"/opt/airflow/transform/normalise_data.py:40: SettingWithCopyWarning: \nA value is trying to be set on a copy of a slice from a DataFrame.\nTry using .loc[row_indexer,col_indexer] = value instead\n\nSee the caveats in the documentation: https://pandas.pydata.org/pandas-docs/stable/user_guide/indexing.html#returning-a-view-versus-a-copy\n  filtered_df['transaction_date'] = filtered_df['transaction_date'].apply(normalise_date)\n","logger":"py.warnings"}
{"timestamp":"2025-09-30T12:22:08.985003","level":"warning","event":"/opt/airflow/transform/normalise_data.py:41: SettingWithCopyWarning: \nA value is trying to be set on a copy of a slice from a DataFrame.\nTry using .loc[row_indexer,col_indexer] = value instead\n\nSee the caveats in the documentation: https://pandas.pydata.org/pandas-docs/stable/user_guide/indexing.html#returning-a-view-versus-a-copy\n  filtered_df['amount'] = pd.to_numeric(filtered_df['amount'].astype(str).str.replace(r\"[^\\d.-]\",\"\",regex=True),errors='coerce')\n","logger":"py.warnings"}
{"timestamp":"2025-09-30T12:22:08.985115","level":"warning","event":"/opt/airflow/transform/normalise_data.py:42: SettingWithCopyWarning: \nA value is trying to be set on a copy of a slice from a DataFrame.\nTry using .loc[row_indexer,col_indexer] = value instead\n\nSee the caveats in the documentation: https://pandas.pydata.org/pandas-docs/stable/user_guide/indexing.html#returning-a-view-versus-a-copy\n  filtered_df['card_name'] = card_name\n","logger":"py.warnings"}
{"timestamp":"2025-09-30T12:22:09.006732","level":"warning","event":"/opt/airflow/transform/normalise_data.py:40: SettingWithCopyWarning: \nA value is trying to be set on a copy of a slice from a DataFrame.\nTry using .loc[row_indexer,col_indexer] = value instead\n\nSee the caveats in the documentation: https://pandas.pydata.org/pandas-docs/stable/user_guide/indexing.html#returning-a-view-versus-a-copy\n  filtered_df['transaction_date'] = filtered_df['transaction_date'].apply(normalise_date)\n","logger":"py.warnings"}
{"timestamp":"2025-09-30T12:22:09.007142","level":"warning","event":"/opt/airflow/transform/normalise_data.py:41: SettingWithCopyWarning: \nA value is trying to be set on a copy of a slice from a DataFrame.\nTry using .loc[row_indexer,col_indexer] = value instead\n\nSee the caveats in the documentation: https://pandas.pydata.org/pandas-docs/stable/user_guide/indexing.html#returning-a-view-versus-a-copy\n  filtered_df['amount'] = pd.to_numeric(filtered_df['amount'].astype(str).str.replace(r\"[^\\d.-]\",\"\",regex=True),errors='coerce')\n","logger":"py.warnings"}
{"timestamp":"2025-09-30T12:22:09.007395","level":"warning","event":"/opt/airflow/transform/normalise_data.py:42: SettingWithCopyWarning: \nA value is trying to be set on a copy of a slice from a DataFrame.\nTry using .loc[row_indexer,col_indexer] = value instead\n\nSee the caveats in the documentation: https://pandas.pydata.org/pandas-docs/stable/user_guide/indexing.html#returning-a-view-versus-a-copy\n  filtered_df['card_name'] = card_name\n","logger":"py.warnings"}
{"timestamp":"2025-09-30T12:22:09.013595","level":"warning","event":"/opt/airflow/transform/normalise_data.py:40: SettingWithCopyWarning: \nA value is trying to be set on a copy of a slice from a DataFrame.\nTry using .loc[row_indexer,col_indexer] = value instead\n\nSee the caveats in the documentation: https://pandas.pydata.org/pandas-docs/stable/user_guide/indexing.html#returning-a-view-versus-a-copy\n  filtered_df['transaction_date'] = filtered_df['transaction_date'].apply(normalise_date)\n","logger":"py.warnings"}
{"timestamp":"2025-09-30T12:22:09.013870","level":"warning","event":"/opt/airflow/transform/normalise_data.py:41: SettingWithCopyWarning: \nA value is trying to be set on a copy of a slice from a DataFrame.\nTry using .loc[row_indexer,col_indexer] = value instead\n\nSee the caveats in the documentation: https://pandas.pydata.org/pandas-docs/stable/user_guide/indexing.html#returning-a-view-versus-a-copy\n  filtered_df['amount'] = pd.to_numeric(filtered_df['amount'].astype(str).str.replace(r\"[^\\d.-]\",\"\",regex=True),errors='coerce')\n","logger":"py.warnings"}
{"timestamp":"2025-09-30T12:22:09.027356Z","level":"info","event":"gemma3:12b failed for GOOGLE *YouTube Music g.co/helppay#f CA","chan":"stdout","logger":"task"}
{"timestamp":"2025-09-30T12:22:09.027475Z","level":"info","event":"Reason: HTTPConnectionPool(host='localhost', port=11434): Max retries exceeded with url: /v1/chat/completions (Caused by NewConnectionError('<urllib3.connection.HTTPConnection object at 0xffff9b770650>: Failed to establish a new connection: [Errno 111] Connection refused'))","chan":"stdout","logger":"task"}
{"timestamp":"2025-09-30T12:22:09.028010Z","level":"info","event":"gemma3:12b failed for GOOGLE *Google One 855-836-3987 CA","chan":"stdout","logger":"task"}
{"timestamp":"2025-09-30T12:22:09.028066Z","level":"info","event":"Reason: HTTPConnectionPool(host='localhost', port=11434): Max retries exceeded with url: /v1/chat/completions (Caused by NewConnectionError('<urllib3.connection.HTTPConnection object at 0xffff83a5d550>: Failed to establish a new connection: [Errno 111] Connection refused'))","chan":"stdout","logger":"task"}
{"timestamp":"2025-09-30T12:22:09.028459Z","level":"info","event":"gemma3:12b failed for TESLA 877-7983752 CA","chan":"stdout","logger":"task"}
{"timestamp":"2025-09-30T12:22:09.028509Z","level":"info","event":"Reason: HTTPConnectionPool(host='localhost', port=11434): Max retries exceeded with url: /v1/chat/completions (Caused by NewConnectionError('<urllib3.connection.HTTPConnection object at 0xffff83a5f710>: Failed to establish a new connection: [Errno 111] Connection refused'))","chan":"stdout","logger":"task"}
{"timestamp":"2025-09-30T12:22:09.028898Z","level":"info","event":"gemma3:12b failed for COSTCO WHSE #0323 EDISON NJ","chan":"stdout","logger":"task"}
{"timestamp":"2025-09-30T12:22:09.028970Z","level":"info","event":"Reason: HTTPConnectionPool(host='localhost', port=11434): Max retries exceeded with url: /v1/chat/completions (Caused by NewConnectionError('<urllib3.connection.HTTPConnection object at 0xffff83a5eff0>: Failed to establish a new connection: [Errno 111] Connection refused'))","chan":"stdout","logger":"task"}
{"timestamp":"2025-09-30T12:22:09.029494Z","level":"info","event":"gemma3:12b failed for COSTCO WHSE #0323 EDISON NJ","chan":"stdout","logger":"task"}
{"timestamp":"2025-09-30T12:22:09.029555Z","level":"info","event":"Reason: HTTPConnectionPool(host='localhost', port=11434): Max retries exceeded with url: /v1/chat/completions (Caused by NewConnectionError('<urllib3.connection.HTTPConnection object at 0xffff83a5e810>: Failed to establish a new connection: [Errno 111] Connection refused'))","chan":"stdout","logger":"task"}
{"timestamp":"2025-09-30T12:22:09.030141Z","level":"info","event":"gemma3:12b failed for COSTCO GAS #0323 EDISON NJ","chan":"stdout","logger":"task"}
{"timestamp":"2025-09-30T12:22:09.030194Z","level":"info","event":"Reason: HTTPConnectionPool(host='localhost', port=11434): Max retries exceeded with url: /v1/chat/completions (Caused by NewConnectionError('<urllib3.connection.HTTPConnection object at 0xffff95a988c0>: Failed to establish a new connection: [Errno 111] Connection refused'))","chan":"stdout","logger":"task"}
{"timestamp":"2025-09-30T12:22:09.030594Z","level":"info","event":"gemma3:12b failed for MTA-NYCT PAYGO NEW YORK NY","chan":"stdout","logger":"task"}
{"timestamp":"2025-09-30T12:22:09.030648Z","level":"info","event":"Reason: HTTPConnectionPool(host='localhost', port=11434): Max retries exceeded with url: /v1/chat/completions (Caused by NewConnectionError('<urllib3.connection.HTTPConnection object at 0xffff83a5e960>: Failed to establish a new connection: [Errno 111] Connection refused'))","chan":"stdout","logger":"task"}
{"timestamp":"2025-09-30T12:22:09.031023Z","level":"info","event":"gemma3:12b failed for MTA-NYCT PAYGO NEW YORK NY","chan":"stdout","logger":"task"}
{"timestamp":"2025-09-30T12:22:09.031072Z","level":"info","event":"Reason: HTTPConnectionPool(host='localhost', port=11434): Max retries exceeded with url: /v1/chat/completions (Caused by NewConnectionError('<urllib3.connection.HTTPConnection object at 0xffff83a5f200>: Failed to establish a new connection: [Errno 111] Connection refused'))","chan":"stdout","logger":"task"}
{"timestamp":"2025-09-30T12:22:09.031447Z","level":"info","event":"gemma3:12b failed for MTA-NYCT PAYGO NEW YORK NY","chan":"stdout","logger":"task"}
{"timestamp":"2025-09-30T12:22:09.031505Z","level":"info","event":"Reason: HTTPConnectionPool(host='localhost', port=11434): Max retries exceeded with url: /v1/chat/completions (Caused by NewConnectionError('<urllib3.connection.HTTPConnection object at 0xffff83a5f9e0>: Failed to establish a new connection: [Errno 111] Connection refused'))","chan":"stdout","logger":"task"}
{"timestamp":"2025-09-30T12:22:09.031882Z","level":"info","event":"gemma3:12b failed for GOOGLE *Google One g.co/HelpPay# CA","chan":"stdout","logger":"task"}
{"timestamp":"2025-09-30T12:22:09.031932Z","level":"info","event":"Reason: HTTPConnectionPool(host='localhost', port=11434): Max retries exceeded with url: /v1/chat/completions (Caused by NewConnectionError('<urllib3.connection.HTTPConnection object at 0xffff83a5cc80>: Failed to establish a new connection: [Errno 111] Connection refused'))","chan":"stdout","logger":"task"}
{"timestamp":"2025-09-30T12:22:09.032271Z","level":"info","event":"gemma3:12b failed for GOOGLE *Google One g.co/HelpPay# CA","chan":"stdout","logger":"task"}
{"timestamp":"2025-09-30T12:22:09.032319Z","level":"info","event":"Reason: HTTPConnectionPool(host='localhost', port=11434): Max retries exceeded with url: /v1/chat/completions (Caused by NewConnectionError('<urllib3.connection.HTTPConnection object at 0xffff83a5c260>: Failed to establish a new connection: [Errno 111] Connection refused'))","chan":"stdout","logger":"task"}
{"timestamp":"2025-09-30T12:22:09.032870Z","level":"info","event":"gemma3:12b failed for GOOGLE *YouTube Music g.co/helppay# CA","chan":"stdout","logger":"task"}
{"timestamp":"2025-09-30T12:22:09.032926Z","level":"info","event":"Reason: HTTPConnectionPool(host='localhost', port=11434): Max retries exceeded with url: /v1/chat/completions (Caused by NewConnectionError('<urllib3.connection.HTTPConnection object at 0xffff9bbede80>: Failed to establish a new connection: [Errno 111] Connection refused'))","chan":"stdout","logger":"task"}
{"timestamp":"2025-09-30T12:22:09.033331Z","level":"info","event":"gemma3:12b failed for WAWA 118","chan":"stdout","logger":"task"}
{"timestamp":"2025-09-30T12:22:09.033380Z","level":"info","event":"Reason: HTTPConnectionPool(host='localhost', port=11434): Max retries exceeded with url: /v1/chat/completions (Caused by NewConnectionError('<urllib3.connection.HTTPConnection object at 0xffff83a5ff50>: Failed to establish a new connection: [Errno 111] Connection refused'))","chan":"stdout","logger":"task"}
{"timestamp":"2025-09-30T12:22:09.033764Z","level":"info","event":"gemma3:12b failed for COSTCO GAS #0323 EDISON NJ","chan":"stdout","logger":"task"}
{"timestamp":"2025-09-30T12:22:09.033817Z","level":"info","event":"Reason: HTTPConnectionPool(host='localhost', port=11434): Max retries exceeded with url: /v1/chat/completions (Caused by NewConnectionError('<urllib3.connection.HTTPConnection object at 0xffff83a5fcb0>: Failed to establish a new connection: [Errno 111] Connection refused'))","chan":"stdout","logger":"task"}
{"timestamp":"2025-09-30T12:22:09.034191Z","level":"info","event":"gemma3:12b failed for GOOGLE *Google One 855-536-3987 CA","chan":"stdout","logger":"task"}
{"timestamp":"2025-09-30T12:22:09.034243Z","level":"info","event":"Reason: HTTPConnectionPool(host='localhost', port=11434): Max retries exceeded with url: /v1/chat/completions (Caused by NewConnectionError('<urllib3.connection.HTTPConnection object at 0xffff83a5f740>: Failed to establish a new connection: [Errno 111] Connection refused'))","chan":"stdout","logger":"task"}
{"timestamp":"2025-09-30T12:22:09.034643Z","level":"info","event":"gemma3:12b failed for WEGMANS #050 DOWNINGTOWN PA","chan":"stdout","logger":"task"}
{"timestamp":"2025-09-30T12:22:09.034695Z","level":"info","event":"Reason: HTTPConnectionPool(host='localhost', port=11434): Max retries exceeded with url: /v1/chat/completions (Caused by NewConnectionError('<urllib3.connection.HTTPConnection object at 0xffff83a5f2f0>: Failed to establish a new connection: [Errno 111] Connection refused'))","chan":"stdout","logger":"task"}
{"timestamp":"2025-09-30T12:22:09.035060Z","level":"info","event":"gemma3:12b failed for ROYAL FAIRS #225 DOWNINGTOWN PA","chan":"stdout","logger":"task"}
{"timestamp":"2025-09-30T12:22:09.035112Z","level":"info","event":"Reason: HTTPConnectionPool(host='localhost', port=11434): Max retries exceeded with url: /v1/chat/completions (Caused by NewConnectionError('<urllib3.connection.HTTPConnection object at 0xffff83a5e2a0>: Failed to establish a new connection: [Errno 111] Connection refused'))","chan":"stdout","logger":"task"}
{"timestamp":"2025-09-30T12:22:09.035644Z","level":"info","event":"gemma3:12b failed for WAWA 118 DOWNINGTOWN PA","chan":"stdout","logger":"task"}
{"timestamp":"2025-09-30T12:22:09.036151Z","level":"info","event":"Reason: HTTPConnectionPool(host='localhost', port=11434): Max retries exceeded with url: /v1/chat/completions (Caused by NewConnectionError('<urllib3.connection.HTTPConnection object at 0xffff83bf5550>: Failed to establish a new connection: [Errno 111] Connection refused'))","chan":"stdout","logger":"task"}
{"timestamp":"2025-09-30T12:22:09.036234Z","level":"info","event":"gemma3:12b failed for EXXON PMG NJ 240#B COLONIA NJ","chan":"stdout","logger":"task"}
{"timestamp":"2025-09-30T12:22:09.036282Z","level":"info","event":"Reason: HTTPConnectionPool(host='localhost', port=11434): Max retries exceeded with url: /v1/chat/completions (Caused by NewConnectionError('<urllib3.connection.HTTPConnection object at 0xffff83a5e330>: Failed to establish a new connection: [Errno 111] Connection refused'))","chan":"stdout","logger":"task"}
{"timestamp":"2025-09-30T12:22:09.036749Z","level":"info","event":"gemma3:12b failed for TESLA SUPERCHARGER US 877-7983752 CA","chan":"stdout","logger":"task"}
{"timestamp":"2025-09-30T12:22:09.036804Z","level":"info","event":"Reason: HTTPConnectionPool(host='localhost', port=11434): Max retries exceeded with url: /v1/chat/completions (Caused by NewConnectionError('<urllib3.connection.HTTPConnection object at 0xffff83a5f140>: Failed to establish a new connection: [Errno 111] Connection refused'))","chan":"stdout","logger":"task"}
{"timestamp":"2025-09-30T12:22:09.037223Z","level":"info","event":"gemma3:12b failed for EXXON VARAHI NORTH CONWAY617-79121 CA-1NH","chan":"stdout","logger":"task"}
{"timestamp":"2025-09-30T12:22:09.037294Z","level":"info","event":"Reason: HTTPConnectionPool(host='localhost', port=11434): Max retries exceeded with url: /v1/chat/completions (Caused by NewConnectionError('<urllib3.connection.HTTPConnection object at 0xffff83a5f4a0>: Failed to establish a new connection: [Errno 111] Connection refused'))","chan":"stdout","logger":"task"}
{"timestamp":"2025-09-30T12:22:09.037716Z","level":"info","event":"gemma3:12b failed for EXXON MECHANIC FL #527 GLENH NH","chan":"stdout","logger":"task"}
{"timestamp":"2025-09-30T12:22:09.037770Z","level":"info","event":"Reason: HTTPConnectionPool(host='localhost', port=11434): Max retries exceeded with url: /v1/chat/completions (Caused by NewConnectionError('<urllib3.connection.HTTPConnection object at 0xffff83a5c920>: Failed to establish a new connection: [Errno 111] Connection refused'))","chan":"stdout","logger":"task"}
{"timestamp":"2025-09-30T12:22:09.038144Z","level":"info","event":"gemma3:12b failed for AMG RETAIL LLC#527 EAST HARTFORD CT","chan":"stdout","logger":"task"}
{"timestamp":"2025-09-30T12:22:09.038209Z","level":"info","event":"Reason: HTTPConnectionPool(host='localhost', port=11434): Max retries exceeded with url: /v1/chat/completions (Caused by NewConnectionError('<urllib3.connection.HTTPConnection object at 0xffff83a5c620>: Failed to establish a new connection: [Errno 111] Connection refused'))","chan":"stdout","logger":"task"}
{"timestamp":"2025-09-30T12:22:09.038741Z","level":"info","event":"gemma3:12b failed for PTC EZ PASS AUTO RE: 877-736-6727 CT","chan":"stdout","logger":"task"}
{"timestamp":"2025-09-30T12:22:09.038808Z","level":"info","event":"Reason: HTTPConnectionPool(host='localhost', port=11434): Max retries exceeded with url: /v1/chat/completions (Caused by NewConnectionError('<urllib3.connection.HTTPConnection object at 0xffff83bc76b0>: Failed to establish a new connection: [Errno 111] Connection refused'))","chan":"stdout","logger":"task"}
{"timestamp":"2025-09-30T12:22:09.039202Z","level":"info","event":"gemma3:12b failed for GOOGLE *YouTube Music g.co/helppay# CA","chan":"stdout","logger":"task"}
{"timestamp":"2025-09-30T12:22:09.039268Z","level":"info","event":"Reason: HTTPConnectionPool(host='localhost', port=11434): Max retries exceeded with url: /v1/chat/completions (Caused by NewConnectionError('<urllib3.connection.HTTPConnection object at 0xffff83a5c200>: Failed to establish a new connection: [Errno 111] Connection refused'))","chan":"stdout","logger":"task"}
{"timestamp":"2025-09-30T12:22:09.039701Z","level":"info","event":"gemma3:12b failed for PTC EZ PASS AUTO RE: 877-736-6727 PA","chan":"stdout","logger":"task"}
{"timestamp":"2025-09-30T12:22:09.040057Z","level":"info","event":"Reason: HTTPConnectionPool(host='localhost', port=11434): Max retries exceeded with url: /v1/chat/completions (Caused by NewConnectionError('<urllib3.connection.HTTPConnection object at 0xffff83a5d820>: Failed to establish a new connection: [Errno 111] Connection refused'))","chan":"stdout","logger":"task"}
{"timestamp":"2025-09-30T12:22:09.040147Z","level":"info","event":"gemma3:12b failed for TESLA SUPERCHARGER US 877-7983752 CA","chan":"stdout","logger":"task"}
{"timestamp":"2025-09-30T12:22:09.040208Z","level":"info","event":"Reason: HTTPConnectionPool(host='localhost', port=11434): Max retries exceeded with url: /v1/chat/completions (Caused by NewConnectionError('<urllib3.connection.HTTPConnection object at 0xffff83a5f620>: Failed to establish a new connection: [Errno 111] Connection refused'))","chan":"stdout","logger":"task"}
{"timestamp":"2025-09-30T12:22:09.040690Z","level":"info","event":"gemma3:12b failed for GOOGLE *Google One 855-836-3987 CA","chan":"stdout","logger":"task"}
{"timestamp":"2025-09-30T12:22:09.040815Z","level":"info","event":"Reason: HTTPConnectionPool(host='localhost', port=11434): Max retries exceeded with url: /v1/chat/completions (Caused by NewConnectionError('<urllib3.connection.HTTPConnection object at 0xffff83a5d550>: Failed to establish a new connection: [Errno 111] Connection refused'))","chan":"stdout","logger":"task"}
{"timestamp":"2025-09-30T12:22:09.045104","level":"warning","event":"/opt/airflow/transform/normalise_data.py:40: SettingWithCopyWarning: \nA value is trying to be set on a copy of a slice from a DataFrame.\nTry using .loc[row_indexer,col_indexer] = value instead\n\nSee the caveats in the documentation: https://pandas.pydata.org/pandas-docs/stable/user_guide/indexing.html#returning-a-view-versus-a-copy\n  filtered_df['transaction_date'] = filtered_df['transaction_date'].apply(normalise_date)\n","logger":"py.warnings"}
{"timestamp":"2025-09-30T12:22:09.045579","level":"warning","event":"/opt/airflow/transform/normalise_data.py:41: SettingWithCopyWarning: \nA value is trying to be set on a copy of a slice from a DataFrame.\nTry using .loc[row_indexer,col_indexer] = value instead\n\nSee the caveats in the documentation: https://pandas.pydata.org/pandas-docs/stable/user_guide/indexing.html#returning-a-view-versus-a-copy\n  filtered_df['amount'] = pd.to_numeric(filtered_df['amount'].astype(str).str.replace(r\"[^\\d.-]\",\"\",regex=True),errors='coerce')\n","logger":"py.warnings"}
{"timestamp":"2025-09-30T12:22:09.045725","level":"warning","event":"/opt/airflow/transform/normalise_data.py:42: SettingWithCopyWarning: \nA value is trying to be set on a copy of a slice from a DataFrame.\nTry using .loc[row_indexer,col_indexer] = value instead\n\nSee the caveats in the documentation: https://pandas.pydata.org/pandas-docs/stable/user_guide/indexing.html#returning-a-view-versus-a-copy\n  filtered_df['card_name'] = card_name\n","logger":"py.warnings"}
{"timestamp":"2025-09-30T12:22:09.047292Z","level":"info","event":"gemma3:12b failed for THANK YOU","chan":"stdout","logger":"task"}
{"timestamp":"2025-09-30T12:22:09.047340Z","level":"info","event":"Reason: HTTPConnectionPool(host='localhost', port=11434): Max retries exceeded with url: /v1/chat/completions (Caused by NewConnectionError('<urllib3.connection.HTTPConnection object at 0xffff9b7f18e0>: Failed to establish a new connection: [Errno 111] Connection refused'))","chan":"stdout","logger":"task"}
{"timestamp":"2025-09-30T12:22:09.047739Z","level":"info","event":"gemma3:12b failed for $73.90","chan":"stdout","logger":"task"}
{"timestamp":"2025-09-30T12:22:09.047804Z","level":"info","event":"Reason: HTTPConnectionPool(host='localhost', port=11434): Max retries exceeded with url: /v1/chat/completions (Caused by NewConnectionError('<urllib3.connection.HTTPConnection object at 0xffff83a5e3c0>: Failed to establish a new connection: [Errno 111] Connection refused'))","chan":"stdout","logger":"task"}
{"timestamp":"2025-09-30T12:22:09.048182Z","level":"info","event":"gemma3:12b failed for THANK YOU","chan":"stdout","logger":"task"}
{"timestamp":"2025-09-30T12:22:09.048234Z","level":"info","event":"Reason: HTTPConnectionPool(host='localhost', port=11434): Max retries exceeded with url: /v1/chat/completions (Caused by NewConnectionError('<urllib3.connection.HTTPConnection object at 0xffff83a5ee70>: Failed to establish a new connection: [Errno 111] Connection refused'))","chan":"stdout","logger":"task"}
{"timestamp":"2025-09-30T12:22:09.048607Z","level":"info","event":"gemma3:12b failed for $14.82","chan":"stdout","logger":"task"}
{"timestamp":"2025-09-30T12:22:09.048658Z","level":"info","event":"Reason: HTTPConnectionPool(host='localhost', port=11434): Max retries exceeded with url: /v1/chat/completions (Caused by NewConnectionError('<urllib3.connection.HTTPConnection object at 0xffff83a5f4d0>: Failed to establish a new connection: [Errno 111] Connection refused'))","chan":"stdout","logger":"task"}
{"timestamp":"2025-09-30T12:22:09.049090Z","level":"info","event":"gemma3:12b failed for $1,120.00","chan":"stdout","logger":"task"}
{"timestamp":"2025-09-30T12:22:09.049183Z","level":"info","event":"Reason: HTTPConnectionPool(host='localhost', port=11434): Max retries exceeded with url: /v1/chat/completions (Caused by NewConnectionError('<urllib3.connection.HTTPConnection object at 0xffff83a5c530>: Failed to establish a new connection: [Errno 111] Connection refused'))","chan":"stdout","logger":"task"}
{"timestamp":"2025-09-30T12:22:09.049683Z","level":"info","event":"gemma3:12b failed for THANK YOU","chan":"stdout","logger":"task"}
{"timestamp":"2025-09-30T12:22:09.049736Z","level":"info","event":"Reason: HTTPConnectionPool(host='localhost', port=11434): Max retries exceeded with url: /v1/chat/completions (Caused by NewConnectionError('<urllib3.connection.HTTPConnection object at 0xffff9b7f1ac0>: Failed to establish a new connection: [Errno 111] Connection refused'))","chan":"stdout","logger":"task"}
{"timestamp":"2025-09-30T12:22:09.050103Z","level":"info","event":"gemma3:12b failed for $705.50","chan":"stdout","logger":"task"}
{"timestamp":"2025-09-30T12:22:09.050155Z","level":"info","event":"Reason: HTTPConnectionPool(host='localhost', port=11434): Max retries exceeded with url: /v1/chat/completions (Caused by NewConnectionError('<urllib3.connection.HTTPConnection object at 0xffff83a5d400>: Failed to establish a new connection: [Errno 111] Connection refused'))","chan":"stdout","logger":"task"}
{"timestamp":"2025-09-30T12:22:09.050842Z","level":"info","event":"gemma3:12b failed for THANK YOU","chan":"stdout","logger":"task"}
{"timestamp":"2025-09-30T12:22:09.050893Z","level":"info","event":"Reason: HTTPConnectionPool(host='localhost', port=11434): Max retries exceeded with url: /v1/chat/completions (Caused by NewConnectionError('<urllib3.connection.HTTPConnection object at 0xffff83a5e030>: Failed to establish a new connection: [Errno 111] Connection refused'))","chan":"stdout","logger":"task"}
{"timestamp":"2025-09-30T12:22:09.050942Z","level":"info","event":"gemma3:12b failed for BPS'B REWARDS B NEW YORK NY","chan":"stdout","logger":"task"}
{"timestamp":"2025-09-30T12:22:09.050984Z","level":"info","event":"Reason: HTTPConnectionPool(host='localhost', port=11434): Max retries exceeded with url: /v1/chat/completions (Caused by NewConnectionError('<urllib3.connection.HTTPConnection object at 0xffff83a5e690>: Failed to establish a new connection: [Errno 111] Connection refused'))","chan":"stdout","logger":"task"}
{"timestamp":"2025-09-30T12:22:09.051359Z","level":"info","event":"gemma3:12b failed for ONLINE PAYMENT","chan":"stdout","logger":"task"}
{"timestamp":"2025-09-30T12:22:09.051442Z","level":"info","event":"Reason: HTTPConnectionPool(host='localhost', port=11434): Max retries exceeded with url: /v1/chat/completions (Caused by NewConnectionError('<urllib3.connection.HTTPConnection object at 0xffff83a5db20>: Failed to establish a new connection: [Errno 111] Connection refused'))","chan":"stdout","logger":"task"}
{"timestamp":"2025-09-30T12:22:09.052449Z","level":"info","event":"gemma3:12b failed for BPS'B REWARDS PMT NEW YORK NY","chan":"stdout","logger":"task"}
{"timestamp":"2025-09-30T12:22:09.052542Z","level":"info","event":"Reason: HTTPConnectionPool(host='localhost', port=11434): Max retries exceeded with url: /v1/chat/completions (Caused by NewConnectionError('<urllib3.connection.HTTPConnection object at 0xffff83a33bc0>: Failed to establish a new connection: [Errno 111] Connection refused'))","chan":"stdout","logger":"task"}
{"timestamp":"2025-09-30T12:22:09.052899Z","level":"info","event":"gemma3:12b failed for BPS'B REWARD PMT NEW YORK NY","chan":"stdout","logger":"task"}
{"timestamp":"2025-09-30T12:22:09.052967Z","level":"info","event":"Reason: HTTPConnectionPool(host='localhost', port=11434): Max retries exceeded with url: /v1/chat/completions (Caused by NewConnectionError('<urllib3.connection.HTTPConnection object at 0xffff83bf58e0>: Failed to establish a new connection: [Errno 111] Connection refused'))","chan":"stdout","logger":"task"}
{"timestamp":"2025-09-30T12:22:09.053080Z","level":"info","event":"gemma3:12b failed for ONLINE PAYMENT","chan":"stdout","logger":"task"}
{"timestamp":"2025-09-30T12:22:09.053122Z","level":"info","event":"Reason: HTTPConnectionPool(host='localhost', port=11434): Max retries exceeded with url: /v1/chat/completions (Caused by NewConnectionError('<urllib3.connection.HTTPConnection object at 0xffff83a5c5c0>: Failed to establish a new connection: [Errno 111] Connection refused'))","chan":"stdout","logger":"task"}
{"timestamp":"2025-09-30T12:22:09.053641Z","level":"info","event":"gemma3:12b failed for WAWA A 8338 HACKENSACK NJ","chan":"stdout","logger":"task"}
{"timestamp":"2025-09-30T12:22:09.053691Z","level":"info","event":"Reason: HTTPConnectionPool(host='localhost', port=11434): Max retries exceeded with url: /v1/chat/completions (Caused by NewConnectionError('<urllib3.connection.HTTPConnection object at 0xffff83a5e900>: Failed to establish a new connection: [Errno 111] Connection refused'))","chan":"stdout","logger":"task"}
{"timestamp":"2025-09-30T12:22:09.054072Z","level":"info","event":"gemma3:12b failed for REGAL CINEMAS INC","chan":"stdout","logger":"task"}
{"timestamp":"2025-09-30T12:22:09.054133Z","level":"info","event":"Reason: HTTPConnectionPool(host='localhost', port=11434): Max retries exceeded with url: /v1/chat/completions (Caused by NewConnectionError('<urllib3.connection.HTTPConnection object at 0xffff83a5e8a0>: Failed to establish a new connection: [Errno 111] Connection refused'))","chan":"stdout","logger":"task"}
{"timestamp":"2025-09-30T12:22:09.054534Z","level":"info","event":"gemma3:12b failed for THANK YOU","chan":"stdout","logger":"task"}
{"timestamp":"2025-09-30T12:22:09.054606Z","level":"info","event":"Reason: HTTPConnectionPool(host='localhost', port=11434): Max retries exceeded with url: /v1/chat/completions (Caused by NewConnectionError('<urllib3.connection.HTTPConnection object at 0xffff83a5fbc0>: Failed to establish a new connection: [Errno 111] Connection refused'))","chan":"stdout","logger":"task"}
{"timestamp":"2025-09-30T12:22:09.055038Z","level":"info","event":"gemma3:12b failed for $15.73","chan":"stdout","logger":"task"}
{"timestamp":"2025-09-30T12:22:09.055100Z","level":"info","event":"Reason: HTTPConnectionPool(host='localhost', port=11434): Max retries exceeded with url: /v1/chat/completions (Caused by NewConnectionError('<urllib3.connection.HTTPConnection object at 0xffff83a5c3e0>: Failed to establish a new connection: [Errno 111] Connection refused'))","chan":"stdout","logger":"task"}
{"timestamp":"2025-09-30T12:22:09.055971Z","level":"info","event":"gemma3:12b failed for $36.00","chan":"stdout","logger":"task"}
{"timestamp":"2025-09-30T12:22:09.056049Z","level":"info","event":"Reason: HTTPConnectionPool(host='localhost', port=11434): Max retries exceeded with url: /v1/chat/completions (Caused by NewConnectionError('<urllib3.connection.HTTPConnection object at 0xffff84322cf0>: Failed to establish a new connection: [Errno 111] Connection refused'))","chan":"stdout","logger":"task"}
{"timestamp":"2025-09-30T12:22:09.056134Z","level":"info","event":"gemma3:12b failed for $9.00","chan":"stdout","logger":"task"}
{"timestamp":"2025-09-30T12:22:09.056203Z","level":"info","event":"Reason: HTTPConnectionPool(host='localhost', port=11434): Max retries exceeded with url: /v1/chat/completions (Caused by NewConnectionError('<urllib3.connection.HTTPConnection object at 0xffff83a5c7a0>: Failed to establish a new connection: [Errno 111] Connection refused'))","chan":"stdout","logger":"task"}
{"timestamp":"2025-09-30T12:22:09.056589Z","level":"info","event":"gemma3:12b failed for $28.97","chan":"stdout","logger":"task"}
{"timestamp":"2025-09-30T12:22:09.056650Z","level":"info","event":"Reason: HTTPConnectionPool(host='localhost', port=11434): Max retries exceeded with url: /v1/chat/completions (Caused by NewConnectionError('<urllib3.connection.HTTPConnection object at 0xffff83a5f620>: Failed to establish a new connection: [Errno 111] Connection refused'))","chan":"stdout","logger":"task"}
{"timestamp":"2025-09-30T12:22:09.057035Z","level":"info","event":"gemma3:12b failed for $1,875.54","chan":"stdout","logger":"task"}
{"timestamp":"2025-09-30T12:22:09.057096Z","level":"info","event":"Reason: HTTPConnectionPool(host='localhost', port=11434): Max retries exceeded with url: /v1/chat/completions (Caused by NewConnectionError('<urllib3.connection.HTTPConnection object at 0xffff83a5f7a0>: Failed to establish a new connection: [Errno 111] Connection refused'))","chan":"stdout","logger":"task"}
{"timestamp":"2025-09-30T12:22:09.057481Z","level":"info","event":"gemma3:12b failed for THANK YOU","chan":"stdout","logger":"task"}
{"timestamp":"2025-09-30T12:22:09.057819Z","level":"info","event":"Reason: HTTPConnectionPool(host='localhost', port=11434): Max retries exceeded with url: /v1/chat/completions (Caused by NewConnectionError('<urllib3.connection.HTTPConnection object at 0xffff83a5f800>: Failed to establish a new connection: [Errno 111] Connection refused'))","chan":"stdout","logger":"task"}
{"timestamp":"2025-09-30T12:22:09.057908Z","level":"info","event":"gemma3:12b failed for REG DOWNINGTOWN 0385 DOWNINGTOWN PA","chan":"stdout","logger":"task"}
{"timestamp":"2025-09-30T12:22:09.057968Z","level":"info","event":"Reason: HTTPConnectionPool(host='localhost', port=11434): Max retries exceeded with url: /v1/chat/completions (Caused by NewConnectionError('<urllib3.connection.HTTPConnection object at 0xffff83a5eea0>: Failed to establish a new connection: [Errno 111] Connection refused'))","chan":"stdout","logger":"task"}
{"timestamp":"2025-09-30T12:22:09.058426Z","level":"info","event":"gemma3:12b failed for REGAL CINEMAS INC 8778355734 TN","chan":"stdout","logger":"task"}
{"timestamp":"2025-09-30T12:22:09.058487Z","level":"info","event":"Reason: HTTPConnectionPool(host='localhost', port=11434): Max retries exceeded with url: /v1/chat/completions (Caused by NewConnectionError('<urllib3.connection.HTTPConnection object at 0xffff9637f740>: Failed to establish a new connection: [Errno 111] Connection refused'))","chan":"stdout","logger":"task"}
{"timestamp":"2025-09-30T12:22:09.058846Z","level":"info","event":"gemma3:12b failed for BPS*B REWARDS B NEW YORK NY","chan":"stdout","logger":"task"}
{"timestamp":"2025-09-30T12:22:09.059193Z","level":"info","event":"Reason: HTTPConnectionPool(host='localhost', port=11434): Max retries exceeded with url: /v1/chat/completions (Caused by NewConnectionError('<urllib3.connection.HTTPConnection object at 0xffff83a5cb30>: Failed to establish a new connection: [Errno 111] Connection refused'))","chan":"stdout","logger":"task"}
{"timestamp":"2025-09-30T12:22:09.059280Z","level":"info","event":"gemma3:12b failed for BPS*B RENT PMT NEW YORK NY","chan":"stdout","logger":"task"}
{"timestamp":"2025-09-30T12:22:09.059340Z","level":"info","event":"Reason: HTTPConnectionPool(host='localhost', port=11434): Max retries exceeded with url: /v1/chat/completions (Caused by NewConnectionError('<urllib3.connection.HTTPConnection object at 0xffff83a5f230>: Failed to establish a new connection: [Errno 111] Connection refused'))","chan":"stdout","logger":"task"}
{"timestamp":"2025-09-30T12:22:09.059716Z","level":"info","event":"gemma3:12b failed for BPS*B RENT PMT NEW YORK NY","chan":"stdout","logger":"task"}
{"timestamp":"2025-09-30T12:22:09.059780Z","level":"info","event":"Reason: HTTPConnectionPool(host='localhost', port=11434): Max retries exceeded with url: /v1/chat/completions (Caused by NewConnectionError('<urllib3.connection.HTTPConnection object at 0xffff83a5f9e0>: Failed to establish a new connection: [Errno 111] Connection refused'))","chan":"stdout","logger":"task"}
{"timestamp":"2025-09-30T12:22:09.060122Z","level":"info","event":"gemma3:12b failed for ONLINE PAYMENT","chan":"stdout","logger":"task"}
{"timestamp":"2025-09-30T12:22:09.060182Z","level":"info","event":"Reason: HTTPConnectionPool(host='localhost', port=11434): Max retries exceeded with url: /v1/chat/completions (Caused by NewConnectionError('<urllib3.connection.HTTPConnection object at 0xffff83a5f560>: Failed to establish a new connection: [Errno 111] Connection refused'))","chan":"stdout","logger":"task"}
{"timestamp":"2025-09-30T12:22:09.064472","level":"warning","event":"/opt/airflow/transform/normalise_data.py:40: SettingWithCopyWarning: \nA value is trying to be set on a copy of a slice from a DataFrame.\nTry using .loc[row_indexer,col_indexer] = value instead\n\nSee the caveats in the documentation: https://pandas.pydata.org/pandas-docs/stable/user_guide/indexing.html#returning-a-view-versus-a-copy\n  filtered_df['transaction_date'] = filtered_df['transaction_date'].apply(normalise_date)\n","logger":"py.warnings"}
{"timestamp":"2025-09-30T12:22:09.064869","level":"warning","event":"/opt/airflow/transform/normalise_data.py:41: SettingWithCopyWarning: \nA value is trying to be set on a copy of a slice from a DataFrame.\nTry using .loc[row_indexer,col_indexer] = value instead\n\nSee the caveats in the documentation: https://pandas.pydata.org/pandas-docs/stable/user_guide/indexing.html#returning-a-view-versus-a-copy\n  filtered_df['amount'] = pd.to_numeric(filtered_df['amount'].astype(str).str.replace(r\"[^\\d.-]\",\"\",regex=True),errors='coerce')\n","logger":"py.warnings"}
{"timestamp":"2025-09-30T12:22:09.065070","level":"warning","event":"/opt/airflow/transform/normalise_data.py:42: SettingWithCopyWarning: \nA value is trying to be set on a copy of a slice from a DataFrame.\nTry using .loc[row_indexer,col_indexer] = value instead\n\nSee the caveats in the documentation: https://pandas.pydata.org/pandas-docs/stable/user_guide/indexing.html#returning-a-view-versus-a-copy\n  filtered_df['card_name'] = card_name\n","logger":"py.warnings"}
{"timestamp":"2025-09-30T12:22:09.088711","level":"warning","event":"/opt/airflow/transform/normalise_data.py:40: SettingWithCopyWarning: \nA value is trying to be set on a copy of a slice from a DataFrame.\nTry using .loc[row_indexer,col_indexer] = value instead\n\nSee the caveats in the documentation: https://pandas.pydata.org/pandas-docs/stable/user_guide/indexing.html#returning-a-view-versus-a-copy\n  filtered_df['transaction_date'] = filtered_df['transaction_date'].apply(normalise_date)\n","logger":"py.warnings"}
{"timestamp":"2025-09-30T12:22:09.089175","level":"warning","event":"/opt/airflow/transform/normalise_data.py:41: SettingWithCopyWarning: \nA value is trying to be set on a copy of a slice from a DataFrame.\nTry using .loc[row_indexer,col_indexer] = value instead\n\nSee the caveats in the documentation: https://pandas.pydata.org/pandas-docs/stable/user_guide/indexing.html#returning-a-view-versus-a-copy\n  filtered_df['amount'] = pd.to_numeric(filtered_df['amount'].astype(str).str.replace(r\"[^\\d.-]\",\"\",regex=True),errors='coerce')\n","logger":"py.warnings"}
{"timestamp":"2025-09-30T12:22:09.089371","level":"warning","event":"/opt/airflow/transform/normalise_data.py:42: SettingWithCopyWarning: \nA value is trying to be set on a copy of a slice from a DataFrame.\nTry using .loc[row_indexer,col_indexer] = value instead\n\nSee the caveats in the documentation: https://pandas.pydata.org/pandas-docs/stable/user_guide/indexing.html#returning-a-view-versus-a-copy\n  filtered_df['card_name'] = card_name\n","logger":"py.warnings"}
{"timestamp":"2025-09-30T12:22:09.092432","level":"info","event":"Done. Returned value was: /opt/airflow/final_df.csv","logger":"airflow.task.operators.airflow.providers.standard.operators.python.PythonOperator"}
{"timestamp":"2025-09-30T12:22:09.092613","level":"info","event":"Pushing xcom","ti":"RuntimeTaskInstance(id=UUID('01999a92-ac86-7163-8db4-f8e5c7a1c909'), task_id='transform_by_normalising_data', dag_id='LocalIngestionDAG', run_id='scheduled__2025-09-30T12:00:00+00:00', try_number=3, map_index=-1, hostname='4302fa03c294', context_carrier={}, task=<Task(PythonOperator): transform_by_normalising_data>, bundle_instance=LocalDagBundle(name=dags-folder), max_tries=2, start_date=datetime.datetime(2025, 9, 30, 12, 22, 8, 619857, tzinfo=datetime.timezone.utc), end_date=None, state=<TaskInstanceState.RUNNING: 'running'>, is_mapped=False, rendered_map_index=None, log_url='http://localhost:8080/dags/LocalIngestionDAG/runs/scheduled__2025-09-30T12%3A00%3A00%2B00%3A00/tasks/transform_by_normalising_data?try_number=3')","logger":"task"}
